#Expyriment 0.10.0 (Python 3.7.16), .xpe-file, coding: cp1252
#date: Wed Apr 26 2023 11:48:31
#sha1: 485338
#modules: 
#display: size=(800, 600), window_mode=True, open_gl=2
#os: uname_result(system='Windows', node='DESKTOP-DI75JFP', release='10', version='10.0.22621', machine='AMD64', processor='Intel64 Family 6 Model 140 Stepping 1, GenuineIntel')
Time,Type,Event,Value,Detail,Detail2
366,design,log,
#design: #exp: Shams Experiment
#design: #dvn: number_trials,number_flashes,response_key,RT
#design: block_cnt,block_id,trial_cnt,trial_id
366,design,logged,
366,Experiment,started
385,Stimulus,presented,1
4012,Keyboard,received,32,wait
4013,stderr,received,'Traceback (most recent call last):'
4013,stderr,received,'  File "C:\\Users\\monik\\anaconda3\\envs\\expyriment\\lib\\site-packages\\pandas\\core\\indexes\\base.py", line 3361, in get_loc'
4016,stderr,received,'    return self._engine.get_loc(casted_key)'
4017,stderr,received,'  File "pandas\\_libs\\index.pyx", line 76, in pandas._libs.index.IndexEngine.get_loc'
4017,stderr,received,'  File "pandas\\_libs\\index.pyx", line 108, in pandas._libs.index.IndexEngine.get_loc'
4018,stderr,received,'  File "pandas\\_libs\\hashtable_class_helper.pxi", line 5198, in pandas._libs.hashtable.PyObjectHashTable.get_item'
4018,stderr,received,'  File "pandas\\_libs\\hashtable_class_helper.pxi", line 5206, in pandas._libs.hashtable.PyObjectHashTable.get_item'
4019,stderr,received,"KeyError: 'FIXATION'"
4019,stderr,received,'The above exception was the direct cause of the following exception:'
4019,stderr,received,'Traceback (most recent call last):'
4019,stderr,received,'  File "trial_version.py", line 121, in <module>'
4020,stderr,received,"    for c in row['FIXATION']: # c should correspond to the fourth column (FIXATION)"
4021,stderr,received,'  File "C:\\Users\\monik\\anaconda3\\envs\\expyriment\\lib\\site-packages\\pandas\\core\\series.py", line 942, in __getitem__'
4031,stderr,received,'    return self._get_value(key)'
4031,stderr,received,'  File "C:\\Users\\monik\\anaconda3\\envs\\expyriment\\lib\\site-packages\\pandas\\core\\series.py", line 1051, in _get_value'
4033,stderr,received,'    loc = self.index.get_loc(label)'
4033,stderr,received,'  File "C:\\Users\\monik\\anaconda3\\envs\\expyriment\\lib\\site-packages\\pandas\\core\\indexes\\base.py", line 3363, in get_loc'
4036,stderr,received,'    raise KeyError(key) from err'
4037,stderr,received,"KeyError: 'FIXATION'"
